Workbook

Sheet Competencias
B1: Competencias que se formaran en el Segundo Semestre 2026
B2: Curso | C2: 796 - Lenguajes Formales y de Programación
B3: Semestre que aplica | C3: Segundo Semestre 2026
B5: Competencias relacionadas al perfil del egresado (Especifica) | I5: Competencias relacionadas al perfil del egresado (General)
B6: 1 | C6: Demuestra pensamiento crítico, actitud investigativa y rigor analítico en el planteamiento y la resolución de problemas complejos. | I6: 1 | J6: Aplica principios básicos de ingeniería, ciencias de computación y sistemas de información y comunicación, en la formulación y resolución adecuada de problemas complejos.
B7: 2 | C7: Aplica los conocimientos de su disciplina en la elaboración, fundamentación y defensa de argumentos para prevenir y resolver problemas complejos en su campo profesional, identificando y aplicando innovaciones. | I7: 2 | J7: Aplica conocimientos tecnológicos con ética profesional y respetando y cuidando los recursos naturales, humanos y financieros.
B8: 3 | C8: Se comunica correctamente en su lengua oficial y utiliza una lengua extranjera con el dominio requerido para el ejercicio de su profesión. | I8: 3 | J8: Actualiza permanente sus conocimientos relacionados con TIC en general, apoyándose en las estrategias de aprendizaje apropiadas.
B11: No | C11: Tipo | D11: Verbo en Presente | E11: Objeto de la acción | G11: [Palabras conectoreas] Herramientas o metodología | H11: [Palabras conectoreas] Condiciones específicas | J11: Nivel
B12: 1 | C12: General | D12: Analiza | E12: la evolución y clasificación de los lenguajes formales y de programación | G12: mediante la comparación de características, estructuras y paradigmas | H12: para comprender su organización y funcionamiento | J12: Analizar
C13: =D12 & " " & E12 & " " &G12& " " &H12& " " -> Analiza la evolución y clasificación de los lenguajes formales y de programación mediante la comparación de características, estructuras y paradigmas para comprender su organización y funcionamiento
B14: 2 | C14: Especifica | D14: Crea | E14: gramáticas libres de contexto | G14: mediante el análisis sintáctico con herramientas | H14: para reconocer y validar lenguajes formales | J14: Crear
C15: =D14 & " " & E14 & " " &G14& " " &H14& " " -> Crea gramáticas libres de contexto mediante el análisis sintáctico con herramientas para reconocer y validar lenguajes formales
B16: 3 | C16: Especifica | D16: Implementa | E16: analizadores léxicos | G16: utilizando herramientas y conocimientos de AFD | H16: para definir cada estado del autómata y reconocer tokens | J16: Crear
C17: =D16 & " " & E16 & " " &G16& " " &H16& " " -> Implementa analizadores léxicos utilizando herramientas y conocimientos de AFD para definir cada estado del autómata y reconocer tokens
B18: 4 | C18: Especifica | D18: Construir | E18: analizadores sintacticos | G18: utilizando conocimientos de Gramáticas Libres del Contexto, POO, recursividad y programación imperativa | H18: para definir cada regla sintáctica | J18: Crear
C19: =D18 & " " & E18 & " " &G18& " " &H18& " " -> Construir analizadores sintacticos utilizando conocimientos de Gramáticas Libres del Contexto, POO, recursividad y programación imperativa para definir cada regla sintáctica
B20: 5 | C20: Especifica | D20: El estudiante aplica | E20: el análisis sintáctico | G20: mediante el uso de gramáticas formales y técnicas de parsing (descendente o ascendente) | H20: para verificar la estructura gramatical y construir árboles sintácticos que permitan solucionar problemas relacionados con la interpretación de lenguajes formales. | J20: Aplicar
C21: =D20 & " " & E20 & " " &G20& " " &H20& " " -> El estudiante aplica el análisis sintáctico mediante el uso de gramáticas formales y técnicas de parsing (descendente o ascendente) para verificar la estructura gramatical y construir árboles sintácticos que permitan solucionar problemas relacionados con la interpretación de lenguajes formales.
B22: 6 | C22: Especifica | D22: Comprender | E22: el funcionamiento del lenguaje de programación | G22: a través de su aplicación | H22: para la resolución de problemas relacionados con las fases del compilador | J22: Comprender
C23: =D22 & " " & E22 & " " &G22& " " &H22& " " -> Comprender el funcionamiento del lenguaje de programación a través de su aplicación para la resolución de problemas relacionados con las fases del compilador
B24: 7 | C24: Especifica | D24: Crear | E24: analizador léxico y sintáctico | G24: en c++ | H24: para la resolución de problemas relacionados con las fases del compilador | J24: Crear
C25: El estudiante construye aplicaciones mediante el uso de analisis lexico y sintactico utilizando herramientas de procesamiento de lenguajes formales. | L25: Manual de competencias: https://drive.google.com/file/d/1n5es0M20vXxa7i4eLN7pbgTXc2C1dmCQ/view?usp=sharing
L26: Video de como hacer competencias: https://youtu.be/C8Q9dKo4t-w?si=yErgF_ihe1tsaHM0
B28: Si las competencias son las misma que el semetre anterior compartenos tu opinion de porque no se cambiaron
E31: NOTAS Zulma Aguirre
D32: Competencia 2,3 y 7 | E32: En este curso no se permite usar herramientas para generación de gramáticas, autómatas o código fuente.

Sheet Resumen
B2: Resumen de Ponderacion y Horas
B4: Curso | C4: 796 - Lenguajes Formales y de Programación
B5: Semestre que aplica | C5: Segundo Semestre 2026
B6: Total de Puntos del Laboratorio
A8: * Esta sección se auto completa al momento en que se llene a la información de la planificación
A9: ** Tomar como base la distribución realizada por el coordinador del area del curso en el documento de criterios y expectativas
A10: Tipo de Actividad | B10: Ponderacion | C10: Horas utilizadas | D10: Aspectos clave que debe abordar | G10: Valor Maximo Recomendado
A11: Actividades durante el peridodo de laboratorio | B11: =S.2!C7+S.3!C7+S.4!C7+S.5!C7+S.6!C7+S.7!C7+S.8!C7+S.9!C7+S.10!C7+S.11!C7 -> 10 | C11: =S.2!C6+S.3!C6+S.4!C6+S.5!C6+S.6!C6+S.7!C6+S.8!C6+S.9!C6+S.10!C6+S.11!C6 -> 1055 | G11: 10
A12: Proyectos | B12: =Proyectos!C6 -> 65 | C12: =Proyectos!C5 -> 65 | G12: 60
A13: Prácticas | B13: =Practicas!C6 -> 20 | C13: =Practicas!C5 -> 0 | G13: 20
A14: Tareas | B14: =Tareas!C6 -> 5 | C14: =Tareas!C5 -> 14 | G14: 10
A15: Total | B15: =SUM(B11:B14) -> 100 | C15: =SUM(C11:C14) -> 1134 | D15: Validacion | E15: =IFERROR(__xludf.DUMMYFUNCTION("LET( nombres,A11:A14, p,B11:B14, m,G11:G14, t,SUM(p), exceden, IFERROR(TEXTJOIN(""; "", TRUE, FILTER(nombres&"" (""&p&"">""&m&"")"", p>m)), """"), negs, IF(COUNTIF(p,""<0"")>0, ""Hay valores negativos"", """"), totalmsg, IF(t<>100, ""Total ≠"&" 100 (actual ""&t&"")"", """"), excesomsg, IF(exceden<>"""", ""Exceden: ""&exceden, """"), msg, TEXTJOIN("" | "", TRUE, totalmsg, negs, excesomsg), IF(msg="""", ""✅ Distribución válida"", ""❌ Revisar: ""&msg) )"),"❌ Revisar: Exceden: Proyectos (65>60)") -> ❌ Revisar: Exceden: Proyectos (65>60)

Sheet Diseño
B2: Diseño de Contenido Curricular
B4: Curso | C4: 796 - Lenguajes Formales y de Programación
B5: semestre que aplica | C5: Segundo Semestre 2026
B8: No. | C8: Competencia | D8: Nombre de la Unidad | E8: Tema | F8: Subtema | G8: Mes | H8: Semana
B9: 1 | C9: Comprender el funcionamiento del lenguaje de programación a través de su aplicación para la resolución de problemas relacionados con las fases del compilador | D9: Lenguajes de Programacion | E9: Introduccion al lenguaje de Programacion | F9: Historia de la Programacion | G9: Julio | H9: 2
B10: 2 | C10: Comprender el funcionamiento del lenguaje de programación a través de su aplicación para la resolución de problemas relacionados con las fases del compilador | D10: Lenguajes de Programacion | E10: Introduccion al lenguaje de Programacion | F10: Aspectos Basicos de la Programacion | G10: Julio | H10: 2
B11: 3 | C11: Comprender el funcionamiento del lenguaje de programación a través de su aplicación para la resolución de problemas relacionados con las fases del compilador | D11: Lenguajes de Programacion | E11: Introduccion al lenguaje de Programacion | F11: Reglas de Sintaxis | G11: Julio | H11: 2
B12: 4 | C12: Comprender el funcionamiento del lenguaje de programación a través de su aplicación para la resolución de problemas relacionados con las fases del compilador | D12: Lenguajes de Programacion | E12: Introduccion al lenguaje de Programacion | F12: Estructura de un programa | G12: Julio | H12: 2
B13: 5 | C13: Comprender el funcionamiento del lenguaje de programación a través de su aplicación para la resolución de problemas relacionados con las fases del compilador | D13: Lenguajes de Programacion | E13: Buenas Practicas y funciones en Programacion | F13: Convenciones de nombres y estilo de código | G13: Agosto | H13: 3
B14: 6 | C14: Comprender el funcionamiento del lenguaje de programación a través de su aplicación para la resolución de problemas relacionados con las fases del compilador | D14: Lenguajes de Programacion | E14: Buenas Practicas y funciones en Programacion | F14: Gestión de memoria y optimización | G14: Agosto | H14: 3
B15: 7 | C15: Comprender el funcionamiento del lenguaje de programación a través de su aplicación para la resolución de problemas relacionados con las fases del compilador | D15: Lenguajes de Programacion | E15: Buenas Practicas y funciones en Programacion | F15: Definición y uso de métodos y funciones | G15: Agosto | H15: 3
B16: 8 | C16: Comprender el funcionamiento del lenguaje de programación a través de su aplicación para la resolución de problemas relacionados con las fases del compilador | D16: Lenguajes de Programacion | E16: Buenas Practicas y funciones en Programacion | F16: Creación y uso de clases | G16: Agosto | H16: 3
B17: 9 | C17: Comprender el funcionamiento del lenguaje de programación a través de su aplicación para la resolución de problemas relacionados con las fases del compilador | D17: Lenguajes de Programacion | E17: Buenas Practicas y funciones en Programacion | F17: Diferencias entre métodos y funciones | G17: Agosto | H17: 3
B18: 10 | C18: Analiza la evolución y clasificación de los lenguajes formales y de programación mediante la comparación de características, estructuras y paradigmas para comprender su organización y funcionamiento | D18: Lenguajes de Programacion | E18: Estructuras de Datos y Control en Programacion | F18: Arreglos | G18: Agosto | H18: 4
B19: 11 | C19: Analiza la evolución y clasificación de los lenguajes formales y de programación mediante la comparación de características, estructuras y paradigmas para comprender su organización y funcionamiento | D19: Lenguajes de Programacion | E19: Estructuras de Datos y Control en Programacion | F19: Diccionarios y estructuras de Datos | G19: Agosto | H19: 4
B20: 12 | C20: Analiza la evolución y clasificación de los lenguajes formales y de programación mediante la comparación de características, estructuras y paradigmas para comprender su organización y funcionamiento | D20: Lenguajes de Programacion | E20: Estructuras de Datos y Control en Programacion | F20: Iteracion | G20: Agosto | H20: 4
... B89: 81 | C89: Construir analizadores sintacticos utilizando conocimientos de Gramáticas Libres del Contexto, POO, recursividad y programación imperativa para definir cada regla sintáctica | D89: Analisis Sintactico | E89: Automatas de Pila | F89: Autómata de Pila desde Gramática Tipo 2 | G89: Octubre | H89: 11
B90: 82
B91: 83
B92: 84
B93: 85
B94: 86
B95: 87
B96: 88
B97: 89
B98: 90
B99: 91
B100: 92
B101: 93
... B106: 98

Sheet Semana Diagnostico
B2: Diseño de Contenido Curricular
B4: Curso | C4: ='Diseño'!C4 -> 796 - Lenguajes Formales y de Programación
B5: Semana | C5: 1
B6: Tiempo | C6: =B15+B22+B29+B41+B47+C48 -> 55
K8: Estos puntos son recomendaciones de los puntos a tratar durante tu presentacion, si no usaras estos eres libre de agregar mas filas para indicar que haras. En los recuadros de la derecha colocar breve resumen de lo que planeas decir. No debes ser muy especifico seran pequeñas anotaciones que te ayudaran a recordar lo que planeaste
A9: 1. Bienvenida y Presentación | G9: Tiempo Aproximado | H9: =B15 -> 15
G10: No puedes excederte mas de 15 minutos
A11: Nombre y Formacion Academica | B11: NOMBRE, estudiante de Ingeniería en Ciencias y Sistemas, auxiliar de Lenguajes Formales y De Programación
A12: Experiencia docente y profecional | B12: Auxiliar de Lenguajes Formales y de Programación, con experiencia en el desarrollo de aplicaciones y en temas relacionados con compiladores.
A13: Rol del auxiliar dentro del curso (funciones, actividades y apoyo a los estudiantes). | B13: Resolución de dudas, preparación de material, guia en laboratorios.
A14: Expectativas sobre la dinámica del curso | B14: Participación del alumnado, disciplina en los laboratorios y la coneccion de desarrollo de aplicacion de lo teórico a lo práctico.
A15: Tiempo que emplearas | B15: 15
A18: 2. Evaluación de Conocimientos Previos | G18: Tiempo Aproximado | H18: =B22 -> 40
G19: No puedes excederte mas de 45 minutos | K19: En los recuadors de la derecha deberas colocar las preguntas que planeas realizar con sus respectivas respuestas. En el segundo recuadro deberas colocar un breve resumne de lo que tines planificado para la parte practica del curso previo al que estas impartiendo.
A20: Redactaras de 15 a 20 preguntas con sus respectivas respuestas , por lo que debes escoge los temas que evaluaras | B20: 1. En Java, una clase puede heredar de múltiples clases al mismo tiempo. Falso 2. La palabra clave super se utiliza para invocar al constructor de la clase padre. Verdadero 3. En Java, una interfaz puede tener métodos abstractos y métodos con implementación (default y static). Verdadero 4. El modificador private permite que un atributo sea accesible desde cualquier clase. Falso 5. En Java, la sobrecarga de métodos significa definir varios métodos con el mismo nombre pero diferentes parámetros. Verdadero 6. La sobreescritura de métodos (override) ocurre cuando una subclase redefine un método de la superclase. Verdadero 7. En Java, una clase marcada como abstract puede instanciarse directamente. Falso 8. ¿Qué palabra clave se utiliza para evitar que una clase pueda ser heredada? final 9. El polimorfismo en Java permite que un mismo método tenga comportamientos diferentes según el objeto que lo invoque. Verdadero 10. En Swing, el contenedor principal de una aplicación gráfica suele ser JFrame. Verdadero 11. En Swing, un JPanel se utiliza únicamente para mostrar menús. Falso 12. ¿Qué clase de Swing se utiliza para mostrar un cuadro de diálogo simple con un mensaje y botones como “Aceptar” o “Cancelar”? JOptionPane 13. El método setVisible(true) en un JFrame se utiliza para mostrar la ventana en pantalla. Verdadero 14. En Swing, los componentes gráficos como botones, etiquetas o cuadros de texto heredan de la clase JComponent. Verdadero 15. ¿Qué método se utiliza en un JButton para asignarle una acción cuando es presionado? addActionListener()
A21: Redactaras una parte practica para realizar la evaluacion de conocimientos previos | B21: Practica Diagnostica : Programacion Orientada a Objetos en Java = Evaluar conocimientos básicos de programación en java y principios de programación.
A22: Tiempo que emplearas | B22: 40
A25: 3. Presentación de los Estudiantes | G25: Tiempo Aproximado | H25: =B29
G26: No puedes excederte mas de 30 minutos
A27: Seleccion al Azar de 5 Estudiantes | B27: 1. Coloboración de los estudiantes amablemente se les solicitará que se presenten en el curso. | K27: En el primer recuadro colocaras la metodollogia que adoptaras para la eleccion de los estudiantes. En el segundo recuadro colocaras la redaccion de las preguntas que comprendan los siguientes puntos respecto al estudiante: Nombre. Intereses y expectativas sobre el curso. Experiencia previa relacionada con el curso (si aplica). Un dato curioso sobre sí mismo. Consideras que la prueba de conociminetos previos esta acorde al conocimiento que se te brindo en su momento Que tan comodo se sintio con la prueba anterior.
A28: Indica las preguntas que responderan los estudiantes afortunados | B28: 1. Nombre completo. 2. ¿Cuáles son tus intereses y expectativas sobre este curso? 3. ¿Tienes experiencia previa relacionada con el curso o con programación? 4. Un dato curioso sobre ti (puede ser un hobby, gusto).
A29: Tiempo que emplearas
A32: 4. Senso de Horarios de Calificación | G32: Tiempo Aproximado | H32: =B36
A33: Deberas estar recordando que deben contestar el formulario asi mismo dejar el link fijado en la llamada | G33: Esta actividad quedara abierta hasta el fin de la clase. pero emplearas 5 min especificos para la actividad
A34: Link de google forms donde este el cuestionario | K34: Esta actividad te ayudara a realizar un senso de posibles horarios de calificacion y que tus estudiantes esten enterados y puedan preveer los dias de calificacion y asi mismo el horario. Deberas colocar en los reacuadros de la derecha link de Google form libre para correos intitucionales, esto para garantizar una sola respuesta por estudiante. TAmbien deberas colocar los posibles horarios y dias que tentativamente tendrias disponibles. para colocarlos en el google form.
A35: Dias y posibles Horarios de calificacion | B35: La calificación podrá realizarse entre semana, dependiendo de la fecha de entrega de la práctica o proyecto. Se seleccionará el día en el que la mayoría de estudiantes tenga disponibilidad. De forma regular, las calificaciones se llevan a cabo los días sábados.
A36: Tiempo que emplearas
A39: 5. Mostrar Programa del Curso | G39: Tiempo Aproximado | H39: =B41
G40: No puedes excederte mas de 30 minutos
A41: Tiempo que emplearas
A44: 6. Evaluación de Conocimientos del Curso Actual | G44: Tiempo Aproximado | H44: =B47
G45: No puedes excederte mas de 15 minutos
A46: Redactaras 20 preguntas con sus respectivas respuestas | B46: 1. JavaScript fue creado originalmente en 1995 por Brendan Eich. Verdadero 2. JavaScript es un lenguaje compilado. Falso 3. Menciona una buena práctica en JavaScript. Usar nombres de variables descriptivos 4. Las librerías en JavaScript permiten reutilizar código ya escrito. Verdadero 5. En JavaScript, los arreglos pueden contener diferentes tipos de datos en la misma estructura. Verdadero 6. Los diccionarios en JavaScript se representan normalmente con objetos {}. Verdadero 7. ¿Qué ciclo es más adecuado cuando no sabemos cuántas veces se repetirá la iteración? While 8. En JavaScript, para leer y escribir archivos en el navegador se usa directamente fs. Falso 9. Un lenguaje natural es ambiguo y depende del contexto. Verdadero 10. Los lenguajes formales son precisos, definidos por reglas y sin ambigüedad. Verdadero 11. Menciona un ejemplo de lenguaje de programación de tercera generación. C, Java, Python 12. Un intérprete traduce y ejecuta el código instrucción por instrucción. Verdadero 13. El compilador traduce todo el código fuente a un lenguaje máquina antes de ejecutarse. Verdadero 14. La Jerarquía de Chomsky clasifica gramáticas en cuatro tipos. Verdadero 15. Un token es la unidad más pequeña que reconoce un analizador léxico. Verdadero 16. ¿Cómo se llaman los errores detectados por el analizador léxico? Errores léxicos 17. Las expresiones regulares son útiles para definir patrones en cadenas. Verdadero 18. Un autómata finito determinista (AFD) puede tener múltiples transiciones con el mismo símbolo desde un estado. Falso 19. El método del árbol permite la conversión de un AFN a un AFD. Verdadero 20. Los autómatas de pila reconocen lenguajes libres de contexto. Verdadero
A47: Tiempo que emplearas

Sheet S.2
B2: Diseño de la Sesión de Laboratorio
B4: Curso | C4: ='Diseño'!C4 -> 796 - Lenguajes Formales y de Programación
B5: Semana | C5: 2
B6: Tiempo | C6: =H10+H21+H44+H68 -> 110
B7: Ponderación | C7: =B49+B60 -> 0
B8: Validación de Tiempo | C8: =IF(H44<=0, "❌ ERROR: La Actividad 1 debe tener un tiempo mayor a 0.", IF(H21>60, "❌ ERROR: El 'Área de Conocimiento' no puede exceder los 60 min.", IF((H10+H21+H44)<100, "❌ ERROR: El tiempo total debe ser de al menos 100 min.", "✅ VALIDACIÓN CORRECTA"))) -> ✅ VALIDACIÓN CORRECTA
A10: 1. Área Actitudinal (Saber Ser) | G10: Tiempo Aproximado | H10: 5
G11: Tiene que estar en un rango de 3 a 5 minutos
A12: Nombre del Valor | B12: Responsabilidad
A13: Tiempo Aproximado | B13: 5
A14: Descripcion
A15: La responsabilidad implica asumir con seriedad y compromiso cada tarea de aprendizaje, comprendiendo que los conocimientos adquiridos en clase serán la base para proyectos personales, académicos y profesionales.
A17: Como se relaciona con los conocimientos de la sesion y se aplicaria
A18: El estudiante debe ser responsable en practicar la sintaxis básica para evitar errores comunes. Al comprender los fundamentos, podrá aplicarlos luego en proyectos más complejos. Se espera que asuma el rol de programador consciente, que entiende que su código no solo debe funcionar, sino también ser claro, organizado y fácil de mantener.
A21: 2. Área Conocimiento (Saber) | G21: Tiempo Aproximado | H21: 60
G22: No puede exceder los 60 minutos
A23: Competencia a desarrollar | B23: Comprender el funcionamiento del lenguaje de programación a través de su aplicación para la resolución de problemas relacionados con las fases del compilador
A24: Competencia a desarrollar | B24: Comprender aspectos importantes sobre el lenguaje utilizado a través de su aplicación para implementar lo aprendido durante las clases teóricas
A26: 2.1 Contenido
A27: No. | B27: Unidad | D27: Tema | F27: Sub Tema
A28: 1 | B28: =IFERROR(__xludf.DUMMYFUNCTION("FILTER('Diseño'!D:D,'Diseño'!H:H=$C$5)"),"Lenguajes de Programacion") -> Lenguajes de Programacion | D28: =IFERROR(__xludf.DUMMYFUNCTION("FILTER('Diseño'!E:E,'Diseño'!H:H=$C$5)"),"Introduccion al lenguaje de Programacion") -> Introduccion al lenguaje de Programacion | F28: =IFERROR(__xludf.DUMMYFUNCTION("FILTER('Diseño'!F:F,'Diseño'!H:H=$C$5)"),"Historia de la Programacion") -> Historia de la Programacion
A29: 2 | B29: =IFERROR(__xludf.DUMMYFUNCTION("""COMPUTED_VALUE"""),"Lenguajes de Programacion") -> Lenguajes de Programacion | D29: =IFERROR(__xludf.DUMMYFUNCTION("""COMPUTED_VALUE"""),"Introduccion al lenguaje de Programacion") -> Introduccion al lenguaje de Programacion | F29: =IFERROR(__xludf.DUMMYFUNCTION("""COMPUTED_VALUE"""),"Aspectos Basicos de la Programacion") -> Aspectos Basicos de la Programacion
A30: 3 | B30: =IFERROR(__xludf.DUMMYFUNCTION("""COMPUTED_VALUE"""),"Lenguajes de Programacion") -> Lenguajes de Programacion | D30: =IFERROR(__xludf.DUMMYFUNCTION("""COMPUTED_VALUE"""),"Introduccion al lenguaje de Programacion") -> Introduccion al lenguaje de Programacion | F30: =IFERROR(__xludf.DUMMYFUNCTION("""COMPUTED_VALUE"""),"Reglas de Sintaxis") -> Reglas de Sintaxis
A31: 4 | B31: =IFERROR(__xludf.DUMMYFUNCTION("""COMPUTED_VALUE"""),"Lenguajes de Programacion") -> Lenguajes de Programacion | D31: =IFERROR(__xludf.DUMMYFUNCTION("""COMPUTED_VALUE"""),"Introduccion al lenguaje de Programacion") -> Introduccion al lenguaje de Programacion | F31: =IFERROR(__xludf.DUMMYFUNCTION("""COMPUTED_VALUE"""),"Estructura de un programa") -> Estructura de un programa
A32: 5 | B32: Lenguajes de Programacion | D32: Introduccion al lenguaje de Programacion | F32: Reglas de Sintaxis
A33: 6 | B33: Lenguajes de Programacion | D33: Introduccion al lenguaje de Programacion | F33: Estructura de un programa
A34: 7
A36: 2.2 Recursos Educativos
A38: Tipo de Recurso a utilizar | B38: Tipo | C38: Valor maximo recomendado en Minutos | D38: Tiempo Aproximado ( unicamente el valor de minutos ) | I38: Validacion
A39: Presentacion | B39: Obligatorio | C39: 30 | D39: 30 | I39: =IF(D39<=C39,"Correcto", "Corregir") -> Correcto
A40: Video | B40: Obligatorio | C40: 6 | D40: 6 | I40: =IF(D40<=C40,"Correcto", "Corregir") -> Correcto
A41: Lectura | B41: Optativo | C41: 10 | D41: 5 | I41: =IF(D41<=C41,"Correcto", "Corregir") -> Correcto
A42: Ejercicio Demostrativo | B42: Obligatorio | C42: 30 | D42: 30 | I42: =IF(D42<=C42,"Correcto", "Corregir") -> Correcto
A44: 3. Área de Habilidades (Saber Hacer) | G44: Tiempo Aproximado | H44: =B50 -> 35
G45: Tiene que estar en un rango de 30 a 50 minutos
A46: Actividad 1 (Obligatoria)
A47: Competencia que predomina en la actividad | B47: Comprender el funcionamiento del lenguaje de programación a través de su aplicación para la resolución de problemas relacionados con las fases del compilador
A48: Tipo de Actividad | B48: Cuestionario
A49: Ponderación | B49: 0
A50: Tiempo Aproximado | B50: 35
...

Sheet S.3
B2: Diseño de la Sesión de Laboratorio
B4: Curso | C4: ='Diseño'!C4 -> 796 - Lenguajes Formales y de Programación
B5: Semana | C5: 3
B6: Tiempo | C6: =H10+H21+H44+H68 -> 105
B7: Ponderación | C7: =B49+B60 -> 0
B8: Validación de Tiempo | C8: =IF(H44<=0, "❌ ERROR: La Actividad 1 debe tener un tiempo mayor a 0.", IF(H21>60, "❌ ERROR: El 'Área de Conocimiento' no puede exceder los 60 min.", IF((H10+H21+H44)<100, "❌ ERROR: El tiempo total debe ser de al menos 100 min.", "✅ VALIDACIÓN CORRECTA"))) -> ✅ VALIDACIÓN CORRECTA
A10: 1. Área Actitudinal (Saber Ser) | G10: Tiempo Aproximado | H10: 5
G11: Tiene que estar en un rango de 3 a 5 minutos
A12: Nombre del Valor | B12: Disciplina
A13: Tiempo Aproximado | B13: 5
A14: Descripcion
A15: La disciplina se refiere a la constancia y la capacidad de mantener un hábito de estudio ordenado y enfocado.
A17: Como se relaciona con los conocimientos de la sesion y se aplicaria
A18: El estudiante necesita ser disciplinado para aprender y practicar la sintaxis del lenguaje de manera correcta. Requiere orden para aplicar las buenas prácticas de programación (como nombrar variables correctamente o comentar el código).
A21: 2. Área Conocimiento (Saber) | G21: Tiempo Aproximado | H21: 60
G22: No puede exceder los 60 minutos
A23: Competencia a desarrollar
A24: Competencia a desarrollar
A26: 2.1 Contenido
A27: No. | B27: Unidad | D27: Tema | F27: Sub Tema
A28: 1 | B28: =IFERROR(__xludf.DUMMYFUNCTION("FILTER('Diseño'!D:D,'Diseño'!H:H=$C$5)"),"Lenguajes de Programacion") -> Lenguajes de Programacion | D28: =IFERROR(__xludf.DUMMYFUNCTION("FILTER('Diseño'!E:E,'Diseño'!H:H=$C$5)"),"Buenas Practicas y funciones en Programacion") -> Buenas Practicas y funciones en Programacion | F28: =IFERROR(__xludf.DUMMYFUNCTION("FILTER('Diseño'!F:F,'Diseño'!H:H=$C$5)"),"Convenciones de nombres y estilo de código") -> Convenciones de nombres y estilo de código
A29: 2 | B29: =IFERROR(__xludf.DUMMYFUNCTION("""COMPUTED_VALUE"""),"Lenguajes de Programacion") -> Lenguajes de Programacion | D29: =IFERROR(__xludf.DUMMYFUNCTION("""COMPUTED_VALUE"""),"Buenas Practicas y funciones en Programacion") -> Buenas Practicas y funciones en Programacion | F29: =IFERROR(__xludf.DUMMYFUNCTION("""COMPUTED_VALUE"""),"Gestión de memoria y optimización") -> Gestión de memoria y optimización
A30: 3 | B30: =IFERROR(__xludf.DUMMYFUNCTION("""COMPUTED_VALUE"""),"Lenguajes de Programacion") -> Lenguajes de Programacion | D30: =IFERROR(__xludf.DUMMYFUNCTION("""COMPUTED_VALUE"""),"Buenas Practicas y funciones en Programacion") -> Buenas Practicas y funciones en Programacion | F30: =IFERROR(__xludf.DUMMYFUNCTION("""COMPUTED_VALUE"""),"Definición y uso de métodos y funciones") -> Definición y uso de métodos y funciones
A31: 4 | B31: =IFERROR(__xludf.DUMMYFUNCTION("""COMPUTED_VALUE"""),"Lenguajes de Programacion") -> Lenguajes de Programacion | D31: =IFERROR(__xludf.DUMMYFUNCTION("""COMPUTED_VALUE"""),"Buenas Practicas y funciones en Programacion") -> Buenas Practicas y funciones en Programacion | F31: =IFERROR(__xludf.DUMMYFUNCTION("""COMPUTED_VALUE"""),"Creación y uso de clases") -> Creación y uso de clases
A32: 5 | B32: =IFERROR(__xludf.DUMMYFUNCTION("""COMPUTED_VALUE"""),"Lenguajes de Programacion") -> Lenguajes de Programacion | D32: =IFERROR(__xludf.DUMMYFUNCTION("""COMPUTED_VALUE"""),"Buenas Practicas y funciones en Programacion") -> Buenas Practicas y funciones en Programacion | F32: =IFERROR(__xludf.DUMMYFUNCTION("""COMPUTED_VALUE"""),"Diferencias entre métodos y funciones") -> Diferencias entre métodos y funciones
A33: 6
A34: 7
A36: 2.2 Recursos Educativos
A38: Tipo de Recurso a utilizar | B38: Tipo | C38: Valor maximo recomendado en Minutos | D38: Tiempo Aproximado ( unicamente el valor de minutos ) | I38: Validacion
A39: Presentacion | B39: Obligatorio | C39: 30 | I39: =IF(D39<=C39,"Correcto", "Corregir") -> Correcto
A40: Video | B40: Obligatorio | C40: 6 | I40: =IF(D40<=C40,"Correcto", "Corregir") -> Correcto
A41: Lectura | B41: Optativo | C41: 10 | I41: =IF(D41<=C41,"Correcto", "Corregir") -> Correcto
A42: Ejercicio Demostrativo | B42: Obligatorio | C42: 30 | I42: =IF(D42<=C42,"Correcto", "Corregir") -> Correcto
A44: 3. Área de Habilidades (Saber Hacer) | G44: Tiempo Aproximado | H44: =B50 -> 35
G45: Tiene que estar en un rango de 30 a 50 minutos
A46: Actividad 1 (Obligatoria)
A47: Competencia que predomina en la actividad
A48: Tipo de Actividad | B48: actividades
A49: Ponderación | B49: 0
A50: Tiempo Aproximado | B50: 35
...

Sheet S.4
B2: Diseño de la Sesión de Laboratorio
B4: Curso | C4: ='Diseño'!C4 -> 796 - Lenguajes Formales y de Programación
B5: Semana | C5: 4
B6: Tiempo | C6: 100
B7: Ponderación | C7: 2
B8: Validación de Tiempo | C8: =IF(H44<=0, "❌ ERROR: La Actividad 1 debe tener un tiempo mayor a 0.", IF(H21>60, "❌ ERROR: El 'Área de Conocimiento' no puede exceder los 60 min.", IF((H10+H21+H44)<100, "❌ ERROR: El tiempo total debe ser de al menos 100 min.", "✅ VALIDACIÓN CORRECTA"))) -> ✅ VALIDACIÓN CORRECTA
A10: 1. Área Actitudinal (Saber Ser) | G10: Tiempo Aproximado | H10: 2
G11: Tiene que estar en un rango de 3 a 5 minutos
A12: Nombre del Valor | B12: Perseverancia
A13: Tiempo Aproximado | B13: 2 minutos
A14: Descripcion
A15: Es la capacidad de mantener el esfuerzo y la determinación para alcanzar una meta a pesar de los obstáculos, las dificultades o los fracasos que puedan surgir en el camino.
A17: Como se relaciona con los conocimientos de la sesion y se aplicaria
A18: Frecuentemente requieren un alto nivel de comprensión llegar a entender el funcionamiento de estructuras de datos.
A21: 2. Área Conocimiento (Saber) | G21: Tiempo Aproximado | H21: =SUM(D39:H42) -> 56
G22: No puede exceder los 60 minutos
A23: Competencia a desarrollar | B23: Analiza la evolución y clasificación de los lenguajes formales y de programación mediante la comparación de características, estructuras y paradigmas para comprender su organización y funcionamiento
A24: Competencia a desarrollar | B24: Analiza la evolución y clasificación de los lenguajes formales y de programación mediante la comparación de características, estructuras y paradigmas para comprender su organización y funcionamiento
A26: 2.1 Contenido
A27: No. | B27: Unidad | D27: Tema | F27: Sub Tema
A28: 1 | B28: =IFERROR(__xludf.DUMMYFUNCTION("FILTER('Diseño'!D:D,'Diseño'!H:H=$C$5)"),"Lenguajes de Programacion") -> Lenguajes de Programacion | D28: =IFERROR(__xludf.DUMMYFUNCTION("FILTER('Diseño'!E:E,'Diseño'!H:H=$C$5)"),"Estructuras de Datos y Control en Programacion") -> Estructuras de Datos y Control en Programacion | F28: =IFERROR(__xludf.DUMMYFUNCTION("FILTER('Diseño'!F:F,'Diseño'!H:H=$C$5)"),"Arreglos") -> Arreglos
A29: 2 | B29: =IFERROR(__xludf.DUMMYFUNCTION("""COMPUTED_VALUE"""),"Lenguajes de Programacion") -> Lenguajes de Programacion | D29: =IFERROR(__xludf.DUMMYFUNCTION("""COMPUTED_VALUE"""),"Estructuras de Datos y Control en Programacion") -> Estructuras de Datos y Control en Programacion | F29: =IFERROR(__xludf.DUMMYFUNCTION("""COMPUTED_VALUE"""),"Diccionarios y estructuras de Datos") -> Diccionarios y estructuras de Datos
A30: 3 | B30: =IFERROR(__xludf.DUMMYFUNCTION("""COMPUTED_VALUE"""),"Lenguajes de Programacion") -> Lenguajes de Programacion | D30: =IFERROR(__xludf.DUMMYFUNCTION("""COMPUTED_VALUE"""),"Estructuras de Datos y Control en Programacion") -> Estructuras de Datos y Control en Programacion | F30: =IFERROR(__xludf.DUMMYFUNCTION("""COMPUTED_VALUE"""),"Iteracion ") -> Iteracion
A31: 4 | B31: =IFERROR(__xludf.DUMMYFUNCTION("""COMPUTED_VALUE"""),"Lenguajes de Programacion") -> Lenguajes de Programacion | D31: =IFERROR(__xludf.DUMMYFUNCTION("""COMPUTED_VALUE"""),"Estructuras de Datos y Control en Programacion") -> Estructuras de Datos y Control en Programacion | F31: =IFERROR(__xludf.DUMMYFUNCTION("""COMPUTED_VALUE"""),"Lectura de Archivos") -> Lectura de Archivos
A32: 5 | B32: =IFERROR(__xludf.DUMMYFUNCTION("""COMPUTED_VALUE"""),"Lenguajes de Programacion") -> Lenguajes de Programacion | D32: =IFERROR(__xludf.DUMMYFUNCTION("""COMPUTED_VALUE"""),"Estructuras de Datos y Control en Programacion") -> Estructuras de Datos y Control en Programacion | F32: =IFERROR(__xludf.DUMMYFUNCTION("""COMPUTED_VALUE"""),"Escritura de Archivos") -> Escritura de Archivos
A33: 6
A34: 7
A36: 2.2 Recursos Educativos
A38: Tipo de Recurso a utilizar | B38: Tipo | C38: Valor maximo recomendado en Minutos | D38: Tiempo Aproximado ( unicamente el valor de minutos ) | I38: Validacion
A39: Presentacion | B39: Obligatorio | C39: 30 | D39: 30 | I39: =IF(D39<=C39,"Correcto", "Corregir") -> Correcto
A40: Video | B40: Obligatorio | C40: 6 | D40: 6 | I40: =IF(D40<=C40,"Correcto", "Corregir") -> Correcto
A41: Lectura | B41: Optativo | C41: 10 | D41: 10 | I41: =IF(D41<=C41,"Correcto", "Corregir") -> Correcto
A42: Ejercicio Demostrativo | B42: Obligatorio | C42: 30 | D42: 10 | I42: =IF(D42<=C42,"Correcto", "Corregir") -> Correcto
A44: 3. Área de Habilidades (Saber Hacer) | G44: Tiempo Aproximado | H44: 50
G45: Tiene que estar en un rango de 30 a 50 minutos
A46: Actividad 1 (Obligatoria)
A47: Competencia que predomina en la actividad | B47: Crea gramáticas libres de contexto mediante el análisis sintáctico con herramientas para reconocer y validar lenguajes formales
A48: Tipo de Actividad | B48: Cuestionario
A49: Ponderación | B49: 0
A50: Tiempo Aproximado | B50: 40
...

Sheet S.5
B2: Diseño de la Sesión de Laboratorio
B4: Curso | C4: ='Diseño'!C4 -> 796 - Lenguajes Formales y de Programación
B5: Semana | C5: 5
B6: Tiempo | C6: 100
B7: Ponderación | C7: =B56+B67 -> 0
B8: Validación de Tiempo | C8: =IF(H51<=0, "❌ ERROR: La Actividad 1 debe tener un tiempo mayor a 0.", IF(H21>60, "❌ ERROR: El 'Área de Conocimiento' no puede exceder los 60 min.", IF((H10+H21+H51)<100, "❌ ERROR: El tiempo total debe ser de al menos 100 min.", "✅ VALIDACIÓN CORRECTA"))) -> ✅ VALIDACIÓN CORRECTA
A10: 1. Área Actitudinal (Saber Ser) | G10: Tiempo Aproximado | H10: =B13 -> 2
G11: Tiene que estar en un rango de 3 a 5 minutos
A12: Nombre del Valor | B12: Pensamiento critico
A13: Tiempo Aproximado | B13: 2
A14: Descripcion
A15: Es la capacidad de analizar, evaluar y cuestionar la información de manera lógica, objetiva y racional para formarse un juicio o tomar decisiones fundamentadas. Implica no aceptar ideas o argumentos sin examinarlos cuidadosamente, considerando la evidencia, los supuestos, las implicaciones y posibles sesgos.
A17: Como se relaciona con los conocimientos de la sesion y se aplicaria
A18: Los lenguajes de programación y su evolución no son solo una cuestión de memorizar reglas, sino también de comprender por qué ciertas decisiones se tomaron en el diseño de lenguajes.
A21: 2. Área Conocimiento (Saber) | G21: Tiempo Aproximado | H21: =SUM(D46:H49) -> 51
G22: No puede exceder los 60 minutos
A23: Competencia a desarrollar | B23: Analiza la evolución y clasificación de los lenguajes formales y de programación mediante la comparación de características, estructuras y paradigmas para comprender su organización y funcionamiento
A24: Competencia a desarrollar | B24: El estudiante construye aplicaciones mediante el uso de analisis lexico y sintactico utilizando herramientas de procesamiento de lenguajes formales.
A26: 2.1 Contenido
A27: No. | B27: Unidad | D27: Tema | F27: Sub Tema
A28: 1 | B28: =IFERROR(__xludf.DUMMYFUNCTION("FILTER('Diseño'!D:D,'Diseño'!H:H=$C$5)"),"Lenguajes Formales") -> Lenguajes Formales | D28: =IFERROR(__xludf.DUMMYFUNCTION("FILTER('Diseño'!E:E,'Diseño'!H:H=$C$5)"),"Lenguajes") -> Lenguajes | F28: =IFERROR(__xludf.DUMMYFUNCTION("FILTER('Diseño'!F:F,'Diseño'!H:H=$C$5)"),"Lenguajes Natural") -> Lenguajes Natural
A29: 2 | B29: =IFERROR(__xludf.DUMMYFUNCTION("""COMPUTED_VALUE"""),"Lenguajes Formales") -> Lenguajes Formales | D29: =IFERROR(__xludf.DUMMYFUNCTION("""COMPUTED_VALUE"""),"Lenguajes") -> Lenguajes | F29: =IFERROR(__xludf.DUMMYFUNCTION("""COMPUTED_VALUE"""),"Lenguajes Formales") -> Lenguajes Formales
A30: 3 | B30: =IFERROR(__xludf.DUMMYFUNCTION("""COMPUTED_VALUE"""),"Lenguajes Formales") -> Lenguajes Formales | D30: =IFERROR(__xludf.DUMMYFUNCTION("""COMPUTED_VALUE"""),"Lenguajes") -> Lenguajes | F30: =IFERROR(__xludf.DUMMYFUNCTION("""COMPUTED_VALUE"""),"Lenguajes de Programacion") -> Lenguajes de Programacion
A31: 4 | B31: =IFERROR(__xludf.DUMMYFUNCTION("""COMPUTED_VALUE"""),"Lenguajes Formales") -> Lenguajes Formales | D31: =IFERROR(__xludf.DUMMYFUNCTION("""COMPUTED_VALUE"""),"Lenguajes") -> Lenguajes | F31: =IFERROR(__xludf.DUMMYFUNCTION("""COMPUTED_VALUE"""),"Evolucion de los Lenguajes de Programacion") -> Evolucion de los Lenguajes de Programacion
A32: 5 | B32: =IFERROR(__xludf.DUMMYFUNCTION("""COMPUTED_VALUE"""),"Lenguajes Formales") -> Lenguajes Formales | D32: =IFERROR(__xludf.DUMMYFUNCTION("""COMPUTED_VALUE"""),"Lenguajes") -> Lenguajes | F32: =IFERROR(__xludf.DUMMYFUNCTION("""COMPUTED_VALUE"""),"Paradigmas") -> Paradigmas
A33: 6 | B33: =IFERROR(__xludf.DUMMYFUNCTION("""COMPUTED_VALUE"""),"Lenguajes Formales") -> Lenguajes Formales | D33: =IFERROR(__xludf.DUMMYFUNCTION("""COMPUTED_VALUE"""),"Lenguajes") -> Lenguajes | F33: =IFERROR(__xludf.DUMMYFUNCTION("""COMPUTED_VALUE"""),"Generaciones de lenguajes de programación") -> Generaciones de lenguajes de programación
A34: 7
A35: 8
A36: 9
A37: 10
A38: 11
A39: 12
A43: 2.2 Recursos Educativos
A45: Tipo de Recurso a utilizar | B45: Tipo | C45: Valor maximo recomendado en Minutos | D45: Tiempo Aproximado ( unicamente el valor de minutos ) | I45: Validacion
A46: Presentacion | B46: Obligatorio | C46: 30 | D46: 25 | I46: =IF(D46<=C46,"Correcto", "Corregir") -> Correcto
A47: Video | B47: Obligatorio | C47: 6 | D47: 6 | I47: =IF(D47<=C47,"Correcto", "Corregir") -> Correcto
A48: Lectura | B48: Optativo | C48: 10 | D48: 10 | I48: =IF(D48<=C48,"Correcto", "Corregir") -> Correcto
A49: Ejercicio Demostrativo | B49: Obligatorio | C49: 30 | D49: 10 | I49: =IF(D49<=C49,"Correcto", "Corregir") -> Correcto
A51: 3. Área de Habilidades (Saber Hacer) | G51: Tiempo Aproximado | H51: =B57 -> 50
G52: Tiene que estar en un rango de 30 a 50 minutos
...

Sheet S.6
B2: Diseño de la Sesión de Laboratorio
B4: Curso | C4: ='Diseño'!C4 -> 796 - Lenguajes Formales y de Programación
B5: Semana | C5: 6
B6: Tiempo | C6: 100
B7: Ponderación | C7: =B49+B60 -> 0
B8: Validación de Tiempo | C8: =IF(H44<=0, "❌ ERROR: La Actividad 1 debe tener un tiempo mayor a 0.", IF(H21>60, "❌ ERROR: El 'Área de Conocimiento' no puede exceder los 60 min.", IF((H10+H21+H44)<100, "❌ ERROR: El tiempo total debe ser de al menos 100 min.", "✅ VALIDACIÓN CORRECTA"))) -> ✅ VALIDACIÓN CORRECTA
A10: 1. Área Actitudinal (Saber Ser) | G10: Tiempo Aproximado | H10: =B13 -> 2
G11: Tiene que estar en un rango de 3 a 5 minutos
A12: Nombre del Valor | B12: Paciencia
A13: Tiempo Aproximado | B13: 2
A14: Descripcion
A15: Es la capacidad de mantener la calma, la serenidad y el control emocional ante situaciones difíciles, retrasos, frustraciones o cuando los resultados deseados tardan en llegar.
A17: Como se relaciona con los conocimientos de la sesion y se aplicaria
A18: Es esencial para superar los obstáculos que se presentan al implementar o estudiar estas herramientas ya que comprender cómo funcionan los compiladores e intérpretes y las estructuras que los componen puede ser desafiante y requerir tiempo.
A21: 2. Área Conocimiento (Saber) | G21: Tiempo Aproximado | H21: =SUM(D39:H42) -> 55
G22: No puede exceder los 60 minutos
A23: Competencia a desarrollar | B23: Analiza la evolución y clasificación de los lenguajes formales y de programación mediante la comparación de características, estructuras y paradigmas para comprender su organización y funcionamiento
A24: Competencia a desarrollar | B24: Implementa analizadores léxicos utilizando herramientas y conocimientos de AFD para definir cada estado del autómata y reconocer tokens
A26: 2.1 Contenido
A27: No. | B27: Unidad | D27: Tema | F27: Sub Tema
A28: 1 | B28: =IFERROR(__xludf.DUMMYFUNCTION("FILTER('Diseño'!D:D,'Diseño'!H:H=$C$5)"),"Lenguajes Formales") -> Lenguajes Formales | D28: =IFERROR(__xludf.DUMMYFUNCTION("FILTER('Diseño'!E:E,'Diseño'!H:H=$C$5)"),"Procesadores de Lenguaje") -> Procesadores de Lenguaje | F28: =IFERROR(__xludf.DUMMYFUNCTION("FILTER('Diseño'!F:F,'Diseño'!H:H=$C$5)"),"Interprete") -> Interprete
A29: 2 | B29: =IFERROR(__xludf.DUMMYFUNCTION("""COMPUTED_VALUE"""),"Lenguajes Formales") -> Lenguajes Formales | D29: =IFERROR(__xludf.DUMMYFUNCTION("""COMPUTED_VALUE"""),"Procesadores de Lenguaje") -> Procesadores de Lenguaje | F29: =IFERROR(__xludf.DUMMYFUNCTION("""COMPUTED_VALUE"""),"Compilador") -> Compilador
A30: 3 | B30: =IFERROR(__xludf.DUMMYFUNCTION("""COMPUTED_VALUE"""),"Lenguajes Formales") -> Lenguajes Formales | D30: =IFERROR(__xludf.DUMMYFUNCTION("""COMPUTED_VALUE"""),"Procesadores de Lenguaje") -> Procesadores de Lenguaje | F30: =IFERROR(__xludf.DUMMYFUNCTION("""COMPUTED_VALUE"""),"Estructura de un compilador") -> Estructura de un compilador
A31: 4 | B31: =IFERROR(__xludf.DUMMYFUNCTION("""COMPUTED_VALUE"""),"Lenguajes Formales") -> Lenguajes Formales | D31: =IFERROR(__xludf.DUMMYFUNCTION("""COMPUTED_VALUE"""),"Procesadores de Lenguaje") -> Procesadores de Lenguaje | F31: =IFERROR(__xludf.DUMMYFUNCTION("""COMPUTED_VALUE"""),"Diferencias y Ejemplos") -> Diferencias y Ejemplos
A32: 5 | B32: =IFERROR(__xludf.DUMMYFUNCTION("""COMPUTED_VALUE"""),"Lenguajes Formales") -> Lenguajes Formales | D32: =IFERROR(__xludf.DUMMYFUNCTION("""COMPUTED_VALUE"""),"Procesadores de Lenguaje") -> Procesadores de Lenguaje | F32: =IFERROR(__xludf.DUMMYFUNCTION("""COMPUTED_VALUE"""),"Herramientas") -> Herramientas
A33: 6 | B33: =IFERROR(__xludf.DUMMYFUNCTION("""COMPUTED_VALUE"""),"Lenguajes Formales") -> Lenguajes Formales | D33: =IFERROR(__xludf.DUMMYFUNCTION("""COMPUTED_VALUE"""),"Procesadores de Lenguaje") -> Procesadores de Lenguaje | F33: =IFERROR(__xludf.DUMMYFUNCTION("""COMPUTED_VALUE"""),"Jerarquia de Chosmky") -> Jerarquia de Chosmky
A34: 7 | B34: =IFERROR(__xludf.DUMMYFUNCTION("""COMPUTED_VALUE"""),"Lenguajes Formales") -> Lenguajes Formales | D34: =IFERROR(__xludf.DUMMYFUNCTION("""COMPUTED_VALUE"""),"Procesadores de Lenguaje") -> Procesadores de Lenguaje | F34: =IFERROR(__xludf.DUMMYFUNCTION("""COMPUTED_VALUE"""),"Clasificacion de Gramaticas") -> Clasificacion de Gramaticas
A36: 2.2 Recursos Educativos
A38: Tipo de Recurso a utilizar | B38: Tipo | C38: Valor maximo recomendado en Minutos | D38: Tiempo Aproximado ( unicamente el valor de minutos ) | I38: Validacion
A39: Presentacion | B39: Obligatorio | C39: 30 | D39: 20 | I39: =IF(D39<=C39,"Correcto", "Corregir") -> Correcto
A40: Video | B40: Obligatorio | C40: 6 | D40: 10 | I40: =IF(D40<=C40,"Correcto", "Corregir") -> Corregir
A41: Lectura | B41: Optativo | C41: 10 | D41: 10 | I41: =IF(D41<=C41,"Correcto", "Corregir") -> Correcto
A42: Ejercicio Demostrativo | B42: Obligatorio | C42: 30 | D42: 15 | I42: =IF(D42<=C42,"Correcto", "Corregir") -> Correcto
A44: 3. Área de Habilidades (Saber Hacer) | G44: Tiempo Aproximado | H44: 50
G45: Tiene que estar en un rango de 30 a 50 minutos
A46: Actividad 1 (Obligatoria)
A47: Competencia que predomina en la actividad | B47: Implementa analizadores léxicos utilizando herramientas y conocimientos de AFD para definir cada estado del autómata y reconocer tokens
A48: Tipo de Actividad | B48: actividades
A49: Ponderación | B49: 0
A50: Tiempo Aproximado | B50: 30
...

Sheet S.7
B2: Diseño de la Sesión de Laboratorio
B4: Curso | C4: ='Diseño'!C4 -> 796 - Lenguajes Formales y de Programación
B5: Semana | C5: 7
B6: Tiempo | C6: =H10+H21+H53+H77 -> 105
B7: Ponderación | C7: =B58+B69 -> 2
B8: Validación de Tiempo | C8: =IF(H53<=0, "❌ ERROR: La Actividad 1 debe tener un tiempo mayor a 0.", IF(H21>60, "❌ ERROR: El 'Área de Conocimiento' no puede exceder los 60 min.", IF((H10+H21+H53)<100, "❌ ERROR: El tiempo total debe ser de al menos 100 min.", "✅ VALIDACIÓN CORRECTA"))) -> ✅ VALIDACIÓN CORRECTA
A10: 1. Área Actitudinal (Saber Ser) | G10: Tiempo Aproximado | H10: 5
G11: Tiene que estar en un rango de 3 a 5 minutos
A12: Nombre del Valor | B12: Autoconocimiento
A13: Tiempo Aproximado | B13: 5 minutos
A14: Descripcion
A15: Permite al estudiante identificar sus fortalezas, intereses y aspectos personales relevantes.
A17: Como se relaciona con los conocimientos de la sesion y se aplicaria
A18: El autoconocimiento permite al estudiante reflexionar sobre su proceso de aprendizaje al enfrentar conceptos abstractos como autómatas, gramáticas y análisis léxico/sintáctico.
A21: 2. Área Conocimiento (Saber) | G21: Tiempo Aproximado | H21: 60
G22: No puede exceder los 60 minutos
A23: Competencia a desarrollar | B23: Analiza la evolución y clasificación de los lenguajes formales y de programación mediante la comparación de características, estructuras y paradigmas para comprender su organización y funcionamiento
A24: Competencia a desarrollar | B24: Implementa analizadores léxicos utilizando herramientas y conocimientos de AFD para definir cada estado del autómata y reconocer tokens
A26: 2.1 Contenido
A27: No. | B27: Unidad | D27: Tema | F27: Sub Tema
A28: 1 | B28: =IFERROR(__xludf.DUMMYFUNCTION("FILTER('Diseño'!D:D,'Diseño'!H:H=$C$5)"),"Analisis Lexico") -> Analisis Lexico | D28: =IFERROR(__xludf.DUMMYFUNCTION("FILTER('Diseño'!E:E,'Diseño'!H:H=$C$5)"),"Definicion y Funcion del analizador lexico") -> Definicion y Funcion del analizador lexico | F28: =IFERROR(__xludf.DUMMYFUNCTION("FILTER('Diseño'!F:F,'Diseño'!H:H=$C$5)"),"Patrones") -> Patrones
A29: 2 | B29: =IFERROR(__xludf.DUMMYFUNCTION("""COMPUTED_VALUE"""),"Analisis Lexico") -> Analisis Lexico | D29: =IFERROR(__xludf.DUMMYFUNCTION("""COMPUTED_VALUE"""),"Definicion y Funcion del analizador lexico") -> Definicion y Funcion del analizador lexico | F29: =IFERROR(__xludf.DUMMYFUNCTION("""COMPUTED_VALUE"""),"Tokens") -> Tokens
A30: 3 | B30: =IFERROR(__xludf.DUMMYFUNCTION("""COMPUTED_VALUE"""),"Analisis Lexico") -> Analisis Lexico | D30: =IFERROR(__xludf.DUMMYFUNCTION("""COMPUTED_VALUE"""),"Definicion y Funcion del analizador lexico") -> Definicion y Funcion del analizador lexico | F30: =IFERROR(__xludf.DUMMYFUNCTION("""COMPUTED_VALUE"""),"Lexemas") -> Lexemas
A31: 4 | B31: =IFERROR(__xludf.DUMMYFUNCTION("""COMPUTED_VALUE"""),"Analisis Lexico") -> Analisis Lexico | D31: =IFERROR(__xludf.DUMMYFUNCTION("""COMPUTED_VALUE"""),"Definicion y Funcion del analizador lexico") -> Definicion y Funcion del analizador lexico | F31: =IFERROR(__xludf.DUMMYFUNCTION("""COMPUTED_VALUE"""),"Errores Lexicos") -> Errores Lexicos
A32: 5 | B32: =IFERROR(__xludf.DUMMYFUNCTION("""COMPUTED_VALUE"""),"Analisis Lexico") -> Analisis Lexico | D32: =IFERROR(__xludf.DUMMYFUNCTION("""COMPUTED_VALUE"""),"Definicion y Funcion del analizador lexico") -> Definicion y Funcion del analizador lexico | F32: =IFERROR(__xludf.DUMMYFUNCTION("""COMPUTED_VALUE"""),"Ejemplos de tokens en diferentes lenguajes") -> Ejemplos de tokens en diferentes lenguajes
A33: 6 | B33: =IFERROR(__xludf.DUMMYFUNCTION("""COMPUTED_VALUE"""),"Analisis Lexico") -> Analisis Lexico | D33: =IFERROR(__xludf.DUMMYFUNCTION("""COMPUTED_VALUE"""),"Operaciones Entre Lenguajes y Expresiones regulares") -> Operaciones Entre Lenguajes y Expresiones regulares | F33: =IFERROR(__xludf.DUMMYFUNCTION("""COMPUTED_VALUE"""),"Interoperabilidad entre Lenguajes") -> Interoperabilidad entre Lenguajes
A34: 7 | B34: =IFERROR(__xludf.DUMMYFUNCTION("""COMPUTED_VALUE"""),"Analisis Lexico") -> Analisis Lexico | D34: =IFERROR(__xludf.DUMMYFUNCTION("""COMPUTED_VALUE"""),"Operaciones Entre Lenguajes y Expresiones regulares") -> Operaciones Entre Lenguajes y Expresiones regulares | F34: =IFERROR(__xludf.DUMMYFUNCTION("""COMPUTED_VALUE"""),"Concepto de interoperabilidad") -> Concepto de interoperabilidad
A35: 8 | B35: =IFERROR(__xludf.DUMMYFUNCTION("""COMPUTED_VALUE"""),"Analisis Lexico") -> Analisis Lexico | D35: =IFERROR(__xludf.DUMMYFUNCTION("""COMPUTED_VALUE"""),"Operaciones Entre Lenguajes y Expresiones regulares") -> Operaciones Entre Lenguajes y Expresiones regulares | F35: =IFERROR(__xludf.DUMMYFUNCTION("""COMPUTED_VALUE"""),"Traducción y Compilación:Proceso de traducción de un lenguaje a otro") -> Traducción y Compilación:Proceso de traducción de un lenguaje a otro
A36: 9 | B36: =IFERROR(__xludf.DUMMYFUNCTION("""COMPUTED_VALUE"""),"Analisis Lexico") -> Analisis Lexico | D36: =IFERROR(__xludf.DUMMYFUNCTION("""COMPUTED_VALUE"""),"Operaciones Entre Lenguajes y Expresiones regulares") -> Operaciones Entre Lenguajes y Expresiones regulares | F36: =IFERROR(__xludf.DUMMYFUNCTION("""COMPUTED_VALUE"""),"Buenas Prácticas en Interoperabilidad") -> Buenas Prácticas en Interoperabilidad
A37: 10 | B37: =IFERROR(__xludf.DUMMYFUNCTION("""COMPUTED_VALUE"""),"Analisis Lexico") -> Analisis Lexico | D37: =IFERROR(__xludf.DUMMYFUNCTION("""COMPUTED_VALUE"""),"Operaciones Entre Lenguajes y Expresiones regulares") -> Operaciones Entre Lenguajes y Expresiones regulares | F37: =IFERROR(__xludf.DUMMYFUNCTION("""COMPUTED_VALUE"""),"¿Qué son las expresiones regulares?") -> ¿Qué son las expresiones regulares?
A38: 11 | B38: =IFERROR(__xludf.DUMMYFUNCTION("""COMPUTED_VALUE"""),"Analisis Lexico") -> Analisis Lexico | D38: =IFERROR(__xludf.DUMMYFUNCTION("""COMPUTED_VALUE"""),"Operaciones Entre Lenguajes y Expresiones regulares") -> Operaciones Entre Lenguajes y Expresiones regulares | F38: =IFERROR(__xludf.DUMMYFUNCTION("""COMPUTED_VALUE"""),"Aplicaciones de Expresiones Regulares en Análisis Léxico") -> Aplicaciones de Expresiones Regulares en Análisis Léxico
A39: 12 | B39: =IFERROR(__xludf.DUMMYFUNCTION("""COMPUTED_VALUE"""),"Analisis Lexico") -> Analisis Lexico | D39: =IFERROR(__xludf.DUMMYFUNCTION("""COMPUTED_VALUE"""),"Operaciones Entre Lenguajes y Expresiones regulares") -> Operaciones Entre Lenguajes y Expresiones regulares | F39: =IFERROR(__xludf.DUMMYFUNCTION("""COMPUTED_VALUE"""),"Diagrama de transición de estados") -> Diagrama de transición de estados
A40: 13 | B40: =IFERROR(__xludf.DUMMYFUNCTION("""COMPUTED_VALUE"""),"Analisis Lexico") -> Analisis Lexico | D40: =IFERROR(__xludf.DUMMYFUNCTION("""COMPUTED_VALUE"""),"Operaciones Entre Lenguajes y Expresiones regulares") -> Operaciones Entre Lenguajes y Expresiones regulares | F40: =IFERROR(__xludf.DUMMYFUNCTION("""COMPUTED_VALUE"""),"Tablas de Transicion") -> Tablas de Transicion
A45: 2.2 Recursos Educativos
A47: Tipo de Recurso a utilizar | B47: Tipo | C47: Valor maximo recomendado en Minutos | D47: Tiempo Aproximado ( unicamente el valor de minutos ) | I47: Validacion
A48: Presentacion | B48: Obligatorio | C48: 20 a 25 minutos | D48: 25 minutos | I48: Correcto
A49: Video | B49: Obligatorio | C49: 5 a 10 minutos | D49: 10 minutos | I49: =IF(D49<=C49,"Correcto", "Corregir") -> Correcto
A50: Lectura | B50: Optativo | C50: 10 a 15 minutos | D50: 15 minutos | I50: Correcto
A51: Ejercicio Demostrativo | B51: Obligatorio | C51: 5 a 10 minutos | D51: 10 minutos | I51: =IF(D51<=C51,"Correcto", "Corregir") -> Correcto
A53: 3. Área de Habilidades (Saber Hacer) | G53: Tiempo Aproximado | H53: 40
...

Sheet S.8
B2: Diseño de la Sesión de Laboratorio
B4: Curso | C4: ='Diseño'!C4 -> 796 - Lenguajes Formales y de Programación
B5: Semana | C5: 8
B6: Tiempo | C6: =H10+H21+H43+H67 -> 105
B7: Ponderación | C7: =B48+B59 -> 2
B8: Validación de Tiempo | C8: =IF(H43<=0, "❌ ERROR: La Actividad 1 debe tener un tiempo mayor a 0.", IF(H21>60, "❌ ERROR: El 'Área de Conocimiento' no puede exceder los 60 min.", IF((H10+H21+H43)<100, "❌ ERROR: El tiempo total debe ser de al menos 100 min.", "✅ VALIDACIÓN CORRECTA"))) -> ✅ VALIDACIÓN CORRECTA
A10: 1. Área Actitudinal (Saber Ser) | G10: Tiempo Aproximado | H10: 5
G11: Tiene que estar en un rango de 3 a 5 minutos
A12: Nombre del Valor | B12: Curiosidad
A13: Tiempo Aproximado | B13: 5 minutos
A14: Descripcion
A15: Se estimula al presentarse contenidos nuevos que despiertan interés por aprender.
A17: Como se relaciona con los conocimientos de la sesion y se aplicaria
A18: La curiosidad es fundamental en el estudio de lenguajes formales porque impulsa al estudiante.
A21: 2. Área Conocimiento (Saber) | G21: Tiempo Aproximado | H21: 60
G22: No puede exceder los 60 minutos
A23: Competencia a desarrollar | B23: Implementa analizadores léxicos utilizando herramientas y conocimientos de AFD para definir cada estado del autómata y reconocer tokens
A24: Competencia a desarrollar | B24: Analiza la evolución y clasificación de los lenguajes formales y de programación mediante la comparación de características, estructuras y paradigmas para comprender su organización y funcionamiento
A26: 2.1 Contenido
A27: No. | B27: Unidad | D27: Tema | F27: Sub Tema
A28: 1 | B28: =IFERROR(__xludf.DUMMYFUNCTION("FILTER('Diseño'!D:D,'Diseño'!H:H=$C$5)"),"Analisis Lexico") -> Analisis Lexico | D28: =IFERROR(__xludf.DUMMYFUNCTION("FILTER('Diseño'!E:E,'Diseño'!H:H=$C$5)"),"Automata Finitos") -> Automata Finitos | F28: =IFERROR(__xludf.DUMMYFUNCTION("FILTER('Diseño'!F:F,'Diseño'!H:H=$C$5)"),"Definición de AFN") -> Definición de AFN
A29: 2 | B29: =IFERROR(__xludf.DUMMYFUNCTION("""COMPUTED_VALUE"""),"Analisis Lexico") -> Analisis Lexico | D29: =IFERROR(__xludf.DUMMYFUNCTION("""COMPUTED_VALUE"""),"Automata Finitos") -> Automata Finitos | F29: =IFERROR(__xludf.DUMMYFUNCTION("""COMPUTED_VALUE"""),"Estructura de un AFN") -> Estructura de un AFN
A30: 3 | B30: =IFERROR(__xludf.DUMMYFUNCTION("""COMPUTED_VALUE"""),"Analisis Lexico") -> Analisis Lexico | D30: =IFERROR(__xludf.DUMMYFUNCTION("""COMPUTED_VALUE"""),"Automata Finitos") -> Automata Finitos | F30: =IFERROR(__xludf.DUMMYFUNCTION("""COMPUTED_VALUE"""),"Ejemplo de AFN") -> Ejemplo de AFN
A31: 4 | B31: =IFERROR(__xludf.DUMMYFUNCTION("""COMPUTED_VALUE"""),"Analisis Lexico") -> Analisis Lexico | D31: =IFERROR(__xludf.DUMMYFUNCTION("""COMPUTED_VALUE"""),"Automata Finitos") -> Automata Finitos | F31: =IFERROR(__xludf.DUMMYFUNCTION("""COMPUTED_VALUE"""),"Definición de AFD") -> Definición de AFD
A32: 5 | B32: =IFERROR(__xludf.DUMMYFUNCTION("""COMPUTED_VALUE"""),"Analisis Lexico") -> Analisis Lexico | D32: =IFERROR(__xludf.DUMMYFUNCTION("""COMPUTED_VALUE"""),"Automata Finitos") -> Automata Finitos | F32: =IFERROR(__xludf.DUMMYFUNCTION("""COMPUTED_VALUE"""),"Estructura de un AFD") -> Estructura de un AFD
A33: 6 | B33: =IFERROR(__xludf.DUMMYFUNCTION("""COMPUTED_VALUE"""),"Analisis Lexico") -> Analisis Lexico | D33: =IFERROR(__xludf.DUMMYFUNCTION("""COMPUTED_VALUE"""),"Automata Finitos") -> Automata Finitos | F33: =IFERROR(__xludf.DUMMYFUNCTION("""COMPUTED_VALUE"""),"Ejemplo de AFD") -> Ejemplo de AFD
A35: 2.2 Recursos Educativos
A37: Tipo de Recurso a utilizar | B37: Tipo | C37: Valor maximo recomendado en Minutos | D37: Tiempo Aproximado ( unicamente el valor de minutos ) | I37: Validacion
A38: Presentacion | B38: Obligatorio | C38: 20 a 25 minutos | D38: 25 minutos | I38: =IF(D38<=C38,"Correcto", "Corregir") -> Corregir
A39: Video | B39: Obligatorio | C39: 5 a 10 minutos | D39: 10 minutos | I39: =IF(D39<=C39,"Correcto", "Corregir") -> Correcto
A40: Lectura | B40: Optativo | C40: 10 a 15 minutos | D40: 15 minutos | I40: =IF(D40<=C40,"Correcto", "Corregir") -> Corregir
A41: Ejercicio Demostrativo | B41: Obligatorio | C41: 5 a 10 minutos | D41: 10 minutos | I41: =IF(D41<=C41,"Correcto", "Corregir") -> Correcto
A43: 3. Área de Habilidades (Saber Hacer) | G43: Tiempo Aproximado | H43: 40
G44: Tiene que estar en un rango de 30 a 50 minutos
A45: Actividad 1 (Obligatoria)
A46: Competencia que predomina en la actividad | B46: Implementa analizadores léxicos utilizando herramientas y conocimientos de AFD para definir cada estado del autómata y reconocer tokens
A47: Tipo de Actividad | B47: Ejercicio practico
A48: Ponderación | B48: 2
A49: Tiempo Aproximado | B49: 40 minutos
A50: Coloca el tiempo que usar en la actividad, un tiempo sugerido 30 minutos
...

Sheet S.9
B2: Diseño de la Sesión de Laboratorio
B4: Curso | C4: ='Diseño'!C4 -> 796 - Lenguajes Formales y de Programación
B5: Semana | C5: 9
B6: Tiempo | C6: =H10+H21+H40+H64 -> 105
B7: Ponderación | C7: =B45+B56 -> 2
B8: Validación de Tiempo | C8: =IF(H40<=0, "❌ ERROR: La Actividad 1 debe tener un tiempo mayor a 0.", IF(H21>60, "❌ ERROR: El 'Área de Conocimiento' no puede exceder los 60 min.", IF((H10+H21+H40)<100, "❌ ERROR: El tiempo total debe ser de al menos 100 min.", "✅ VALIDACIÓN CORRECTA"))) -> ✅ VALIDACIÓN CORRECTA
A10: 1. Área Actitudinal (Saber Ser) | G10: Tiempo Aproximado | H10: 5
G11: Tiene que estar en un rango de 3 a 5 minutos
A12: Nombre del Valor | B12: Compromiso
A13: Tiempo Aproximado | B13: 5 minutos
A14: Descripcion
A15: Se impulsa al conocer y aceptar activamente el programa del curso.
A17: Como se relaciona con los conocimientos de la sesion y se aplicaria
A18: El compromiso es esencial en el estudio de lenguajes formales porque este campo requiere: Dedicación constante para dominar conceptos abstractos y secuenciales.
A21: 2. Área Conocimiento (Saber) | G21: Tiempo Aproximado | H21: 60
G22: No puede exceder los 60 minutos
A23: Competencia a desarrollar | B23: Implementa analizadores léxicos utilizando herramientas y conocimientos de AFD para definir cada estado del autómata y reconocer tokens
A24: Competencia a desarrollar | B24: Implementar un proyecto de analisis lexico y sintactico con el lenguaje Python y PLY con una interfaz grafica en Tkinter
A26: 2.1 Contenido
A27: No. | B27: Unidad | D27: Tema | F27: Sub Tema
A28: 1 | B28: =IFERROR(__xludf.DUMMYFUNCTION("FILTER('Diseño'!D:D,'Diseño'!H:H=$C$5)"),"Analisis Lexico") -> Analisis Lexico | D28: =IFERROR(__xludf.DUMMYFUNCTION("FILTER('Diseño'!E:E,'Diseño'!H:H=$C$5)"),"Conversion AFN a AFD") -> Conversion AFN a AFD | F28: =IFERROR(__xludf.DUMMYFUNCTION("FILTER('Diseño'!F:F,'Diseño'!H:H=$C$5)"),"Método del Árbol") -> Método del Árbol
A29: 2 | B29: =IFERROR(__xludf.DUMMYFUNCTION("""COMPUTED_VALUE"""),"Analisis Lexico") -> Analisis Lexico | D29: =IFERROR(__xludf.DUMMYFUNCTION("""COMPUTED_VALUE"""),"Conversion AFN a AFD") -> Conversion AFN a AFD | F29: =IFERROR(__xludf.DUMMYFUNCTION("""COMPUTED_VALUE"""),"Anulables") -> Anulables
A30: 3 | B30: =IFERROR(__xludf.DUMMYFUNCTION("""COMPUTED_VALUE"""),"Analisis Lexico") -> Analisis Lexico | D30: =IFERROR(__xludf.DUMMYFUNCTION("""COMPUTED_VALUE"""),"Conversion AFN a AFD") -> Conversion AFN a AFD | F30: =IFERROR(__xludf.DUMMYFUNCTION("""COMPUTED_VALUE"""),"Cálculo de First, Last y Next") -> Cálculo de First, Last y Next
A32: 2.2 Recursos Educativos
A34: Tipo de Recurso a utilizar | B34: Tipo | C34: Valor maximo recomendado en Minutos | D34: Tiempo Aproximado ( unicamente el valor de minutos ) | I34: Validacion
A35: Presentacion | B35: Obligatorio | C35: 20 a 25 minutos | D35: 25 minutos | I35: =IF(D35<=C35,"Correcto", "Corregir") -> Corregir
A36: Video | B36: Obligatorio | C36: 5 a 10 minutos | D36: 10 minutos | I36: =IF(D36<=C36,"Correcto", "Corregir") -> Correcto
A37: Lectura | B37: Optativo | C37: 10 a 15 minutos | D37: 15 minutos | I37: =IF(D37<=C37,"Correcto", "Corregir") -> Corregir
A38: Ejercicio Demostrativo | B38: Obligatorio | C38: 5 a 10 minutos | D38: 10 minutos | I38: =IF(D38<=C38,"Correcto", "Corregir") -> Correcto
A40: 3. Área de Habilidades (Saber Hacer) | G40: Tiempo Aproximado | H40: 40
G41: Tiene que estar en un rango de 30 a 50 minutos
A42: Actividad 1 (Obligatoria)
A43: Competencia que predomina en la actividad | B43: Implementa analizadores léxicos utilizando herramientas y conocimientos de AFD para definir cada estado del autómata y reconocer tokens
